<?xml version="1.0"?>
<robot name="bubble_man">
  
  <!-- Base link: Torso (main body) -->
  <link name="torso">
    <visual>
      <geometry>
        <sphere radius="0.25"/>
      </geometry>
      <material name="torso_color">
        <color rgba="0.8 0.4 0.2 1.0"/>
      </material>
    </visual>
    <collision>
      <geometry>
        <sphere radius="0.25"/>
      </geometry>
    </collision>
    <inertial>
      <mass value="20.0"/>
      <inertia ixx="0.5" ixy="0.0" ixz="0.0" iyy="0.5" iyz="0.0" izz="0.5"/>
    </inertial>
  </link>

  <!-- Head -->
  <link name="head">
    <visual>
      <geometry>
        <sphere radius="0.12"/>
      </geometry>
      <material name="head_color">
        <color rgba="1.0 0.8 0.6 1.0"/>
      </material>
    </visual>
    <collision>
      <geometry>
        <sphere radius="0.12"/>
      </geometry>
    </collision>
    <inertial>
      <mass value="5.0"/>
      <inertia ixx="0.1" ixy="0.0" ixz="0.0" iyy="0.1" iyz="0.0" izz="0.1"/>
    </inertial>
  </link>

  <!-- Neck joint -->
  <joint name="neck" type="revolute">
    <parent link="torso"/>
    <child link="head"/>
    <origin xyz="0 0 0.3" rpy="0 0 0"/>
    <axis xyz="0 0 1"/>
    <limit lower="-1.57" upper="1.57" effort="100" velocity="1.0"/>
  </joint>

  <!-- Left Upper Arm -->
  <link name="left_upper_arm">
    <visual>
      <geometry>
        <sphere radius="0.08"/>
      </geometry>
      <material name="arm_color">
        <color rgba="1.0 0.8 0.6 1.0"/>
      </material>
    </visual>
    <collision>
      <geometry>
        <sphere radius="0.08"/>
      </geometry>
    </collision>
    <inertial>
      <mass value="3.0"/>
      <inertia ixx="0.05" ixy="0.0" ixz="0.0" iyy="0.05" iyz="0.0" izz="0.05"/>
    </inertial>
  </link>

  <!-- Left shoulder joint -->
  <joint name="left_shoulder" type="revolute">
    <parent link="torso"/>
    <child link="left_upper_arm"/>
    <origin xyz="-0.3 0 0.1" rpy="0 0 0"/>
    <axis xyz="0 1 0"/>
    <limit lower="-3.14" upper="3.14" effort="100" velocity="1.0"/>
  </joint>

  <!-- Left Lower Arm -->
  <link name="left_lower_arm">
    <visual>
      <geometry>
        <sphere radius="0.06"/>
      </geometry>
      <material name="arm_color">
        <color rgba="1.0 0.8 0.6 1.0"/>
      </material>
    </visual>
    <collision>
      <geometry>
        <sphere radius="0.06"/>
      </geometry>
    </collision>
    <inertial>
      <mass value="2.0"/>
      <inertia ixx="0.02" ixy="0.0" ixz="0.0" iyy="0.02" iyz="0.0" izz="0.02"/>
    </inertial>
  </link>

  <!-- Left elbow joint -->
  <joint name="left_elbow" type="revolute">
    <parent link="left_upper_arm"/>
    <child link="left_lower_arm"/>
    <origin xyz="-0.2 0 0" rpy="0 0 0"/>
    <axis xyz="0 1 0"/>
    <limit lower="0" upper="2.35" effort="100" velocity="1.0"/>
  </joint>

  <!-- Left Hand -->
  <link name="left_hand">
    <visual>
      <geometry>
        <sphere radius="0.05"/>
      </geometry>
      <material name="hand_color">
        <color rgba="1.0 0.7 0.5 1.0"/>
      </material>
    </visual>
    <collision>
      <geometry>
        <sphere radius="0.05"/>
      </geometry>
    </collision>
    <inertial>
      <mass value="1.0"/>
      <inertia ixx="0.01" ixy="0.0" ixz="0.0" iyy="0.01" iyz="0.0" izz="0.01"/>
    </inertial>
  </link>

  <!-- Left wrist joint -->
  <joint name="left_wrist" type="revolute">
    <parent link="left_lower_arm"/>
    <child link="left_hand"/>
    <origin xyz="-0.15 0 0" rpy="0 0 0"/>
    <axis xyz="1 0 0"/>
    <limit lower="-1.57" upper="1.57" effort="50" velocity="1.0"/>
  </joint>

  <!-- Right Upper Arm -->
  <link name="right_upper_arm">
    <visual>
      <geometry>
        <sphere radius="0.08"/>
      </geometry>
      <material name="arm_color">
        <color rgba="1.0 0.8 0.6 1.0"/>
      </material>
    </visual>
    <collision>
      <geometry>
        <sphere radius="0.08"/>
      </geometry>
    </collision>
    <inertial>
      <mass value="3.0"/>
      <inertia ixx="0.05" ixy="0.0" ixz="0.0" iyy="0.05" iyz="0.0" izz="0.05"/>
    </inertial>
  </link>

  <!-- Right shoulder joint -->
  <joint name="right_shoulder" type="revolute">
    <parent link="torso"/>
    <child link="right_upper_arm"/>
    <origin xyz="0.3 0 0.1" rpy="0 0 0"/>
    <axis xyz="0 1 0"/>
    <limit lower="-3.14" upper="3.14" effort="100" velocity="1.0"/>
  </joint>

  <!-- Right Lower Arm -->
  <link name="right_lower_arm">
    <visual>
      <geometry>
        <sphere radius="0.06"/>
      </geometry>
      <material name="arm_color">
        <color rgba="1.0 0.8 0.6 1.0"/>
      </material>
    </visual>
    <collision>
      <geometry>
        <sphere radius="0.06"/>
      </geometry>
    </collision>
    <inertial>
      <mass value="2.0"/>
      <inertia ixx="0.02" ixy="0.0" ixz="0.0" iyy="0.02" iyz="0.0" izz="0.02"/>
    </inertial>
  </link>

  <!-- Right elbow joint -->
  <joint name="right_elbow" type="revolute">
    <parent link="right_upper_arm"/>
    <child link="right_lower_arm"/>
    <origin xyz="0.2 0 0" rpy="0 0 0"/>
    <axis xyz="0 1 0"/>
    <limit lower="0" upper="2.35" effort="100" velocity="1.0"/>
  </joint>

  <!-- Right Hand -->
  <link name="right_hand">
    <visual>
      <geometry>
        <sphere radius="0.05"/>
      </geometry>
      <material name="hand_color">
        <color rgba="1.0 0.7 0.5 1.0"/>
      </material>
    </visual>
    <collision>
      <geometry>
        <sphere radius="0.05"/>
      </geometry>
    </collision>
    <inertial>
      <mass value="1.0"/>
      <inertia ixx="0.01" ixy="0.0" ixz="0.0" iyy="0.01" iyz="0.0" izz="0.01"/>
    </inertial>
  </link>

  <!-- Right wrist joint -->
  <joint name="right_wrist" type="revolute">
    <parent link="right_lower_arm"/>
    <child link="right_hand"/>
    <origin xyz="0.15 0 0" rpy="0 0 0"/>
    <axis xyz="1 0 0"/>
    <limit lower="-1.57" upper="1.57" effort="50" velocity="1.0"/>
  </joint>

  <!-- Left Upper Leg -->
  <link name="left_upper_leg">
    <visual>
      <geometry>
        <sphere radius="0.1"/>
      </geometry>
      <material name="leg_color">
        <color rgba="0.2 0.4 0.8 1.0"/>
      </material>
    </visual>
    <collision>
      <geometry>
        <sphere radius="0.1"/>
      </geometry>
    </collision>
    <inertial>
      <mass value="8.0"/>
      <inertia ixx="0.08" ixy="0.0" ixz="0.0" iyy="0.08" iyz="0.0" izz="0.08"/>
    </inertial>
  </link>

  <!-- Left hip joint -->
  <joint name="left_hip" type="revolute">
    <parent link="torso"/>
    <child link="left_upper_leg"/>
    <origin xyz="-0.12 0 -0.3" rpy="0 0 0"/>
    <axis xyz="0 1 0"/>
    <limit lower="-1.57" upper="1.57" effort="150" velocity="1.0"/>
  </joint>

  <!-- Left Lower Leg -->
  <link name="left_lower_leg">
    <visual>
      <geometry>
        <sphere radius="0.08"/>
      </geometry>
      <material name="leg_color">
        <color rgba="0.2 0.4 0.8 1.0"/>
      </material>
    </visual>
    <collision>
      <geometry>
        <sphere radius="0.08"/>
      </geometry>
    </collision>
    <inertial>
      <mass value="5.0"/>
      <inertia ixx="0.04" ixy="0.0" ixz="0.0" iyy="0.04" iyz="0.0" izz="0.04"/>
    </inertial>
  </link>

  <!-- Left knee joint -->
  <joint name="left_knee" type="revolute">
    <parent link="left_upper_leg"/>
    <child link="left_lower_leg"/>
    <origin xyz="0 0 -0.25" rpy="0 0 0"/>
    <axis xyz="0 1 0"/>
    <limit lower="0" upper="2.35" effort="150" velocity="1.0"/>
  </joint>

  <!-- Left Foot -->
  <link name="left_foot">
    <visual>
      <geometry>
        <sphere radius="0.06"/>
      </geometry>
      <material name="foot_color">
        <color rgba="0.3 0.3 0.3 1.0"/>
      </material>
    </visual>
    <collision>
      <geometry>
        <sphere radius="0.06"/>
      </geometry>
    </collision>
    <inertial>
      <mass value="2.0"/>
      <inertia ixx="0.02" ixy="0.0" ixz="0.0" iyy="0.02" iyz="0.0" izz="0.02"/>
    </inertial>
  </link>

  <!-- Left ankle joint -->
  <joint name="left_ankle" type="revolute">
    <parent link="left_lower_leg"/>
    <child link="left_foot"/>
    <origin xyz="0 0 -0.2" rpy="0 0 0"/>
    <axis xyz="0 1 0"/>
    <limit lower="-0.78" upper="0.78" effort="100" velocity="1.0"/>
  </joint>

  <!-- Right Upper Leg -->
  <link name="right_upper_leg">
    <visual>
      <geometry>
        <sphere radius="0.1"/>
      </geometry>
      <material name="leg_color">
        <color rgba="0.2 0.4 0.8 1.0"/>
      </material>
    </visual>
    <collision>
      <geometry>
        <sphere radius="0.1"/>
      </geometry>
    </collision>
    <inertial>
      <mass value="8.0"/>
      <inertia ixx="0.08" ixy="0.0" ixz="0.0" iyy="0.08" iyz="0.0" izz="0.08"/>
    </inertial>
  </link>

  <!-- Right hip joint -->
  <joint name="right_hip" type="revolute">
    <parent link="torso"/>
    <child link="right_upper_leg"/>
    <origin xyz="0.12 0 -0.3" rpy="0 0 0"/>
    <axis xyz="0 1 0"/>
    <limit lower="-1.57" upper="1.57" effort="150" velocity="1.0"/>
  </joint>

  <!-- Right Lower Leg -->
  <link name="right_lower_leg">
    <visual>
      <geometry>
        <sphere radius="0.08"/>
      </geometry>
      <material name="leg_color">
        <color rgba="0.2 0.4 0.8 1.0"/>
      </material>
    </visual>
    <collision>
      <geometry>
        <sphere radius="0.08"/>
      </geometry>
    </collision>
    <inertial>
      <mass value="5.0"/>
      <inertia ixx="0.04" ixy="0.0" ixz="0.0" iyy="0.04" iyz="0.0" izz="0.04"/>
    </inertial>
  </link>

  <!-- Right knee joint -->
  <joint name="right_knee" type="revolute">
    <parent link="right_upper_leg"/>
    <child link="right_lower_leg"/>
    <origin xyz="0 0 -0.25" rpy="0 0 0"/>
    <axis xyz="0 1 0"/>
    <limit lower="0" upper="2.35" effort="150" velocity="1.0"/>
  </joint>

  <!-- Right Foot -->
  <link name="right_foot">
    <visual>
      <geometry>
        <sphere radius="0.06"/>
      </geometry>
      <material name="foot_color">
        <color rgba="0.3 0.3 0.3 1.0"/>
      </material>
    </visual>
    <collision>
      <geometry>
        <sphere radius="0.06"/>
      </geometry>
    </collision>
    <inertial>
      <mass value="2.0"/>
      <inertia ixx="0.02" ixy="0.0" ixz="0.0" iyy="0.02" iyz="0.0" izz="0.02"/>
    </inertial>
  </link>

  <!-- Right ankle joint -->
  <joint name="right_ankle" type="revolute">
    <parent link="right_lower_leg"/>
    <child link="right_foot"/>
    <origin xyz="0 0 -0.2" rpy="0 0 0"/>
    <axis xyz="0 1 0"/>
    <limit lower="-0.78" upper="0.78" effort="100" velocity="1.0"/>
  </joint>

</robot>